<?xml version="1.0" encoding="UTF-8"?>
<robot name="quadrotor_2dof">
  <joint name="Joint_1" type="revolute">
    <origin xyz="0.0290071 0.0007071 0.0837471" rpy="1.5707963 0.1848015 -1.5707963"/>
    <parent link="Motor_1"/>
    <child link="Link_1"/>
    <axis xyz="0. 0. 1."/>
    <limit lower="-1.3962634" upper="1.3962634" effort="10000000." velocity="0."/>
  </joint>
  <joint name="Joint_2" type="revolute">
    <origin xyz="0.0262071 0.026864 0.1332206" rpy="1.4185356 0.0001237 -0.000019 "/>
    <parent link="Motor_2"/>
    <child link="Link_2"/>
    <axis xyz="0. 0. 1."/>
    <limit lower="-0.3490659" upper="1.9198622" effort="10000000." velocity="0."/>
  </joint>
  <joint name="Joint_3" type="revolute">
    <origin xyz="0.3242101 0.0197071 0.1592099" rpy="-2.9151874 1.5707963 1.7972018"/>
    <parent link="Motor_3"/>
    <child link="Link_3"/>
    <axis xyz="0. 0. 1."/>
    <limit lower="-0.1745329" upper="1.0471976" effort="10000000." velocity="0."/>
  </joint>
  <joint name="Motor_1_FixedJoint" type="fixed">
    <origin xyz="0. -0.0006937 0.000603 " rpy="0.0000001 -0.0000001 0. "/>
    <parent link="World"/>
    <child link="Motor_1"/>
  </joint>
  <joint name="Motor_2_FixedJoint" type="fixed">
    <origin xyz="0.0034075 -0.0851375 0.0285071" rpy="-1.6076132 1.5707964 0. "/>
    <parent link="Link_1"/>
    <child link="Motor_2"/>
  </joint>
  <joint name="Motor_3_FixedJoint" type="fixed">
    <origin xyz="-0.0266617 -0.1354437 0.0197133" rpy="-1.5708233 0.0025782 0.0001928"/>
    <parent link="Link_2"/>
    <child link="Motor_3"/>
  </joint>
  <joint name="S500_Rotor_1" type="continuous">
    <origin xyz="0.1623238 0.1633716 0.0677936" rpy="0.0602103 -0.0672136 0.152466 "/>
    <parent link="World"/>
    <child link="Rotors_Rotor_1"/>
    <axis xyz="0. 0. 1."/>
  </joint>
  <joint name="S500_Rotor_2" type="continuous">
    <origin xyz="0.1623238 -0.1635071 0.0691902" rpy="-0.0907014 -0.0343382 0.2701735"/>
    <parent link="World"/>
    <child link="Rotors_Rotor_2"/>
    <axis xyz="0. 0. 1."/>
  </joint>
  <joint name="S500_Rotor_3" type="continuous">
    <origin xyz="-0.1645113 -0.1634835 0.0747046" rpy="-0.0397349 0.1132605 0.3731079"/>
    <parent link="World"/>
    <child link="Rotors_Rotor_3"/>
    <axis xyz="0. 0. 1."/>
  </joint>
  <joint name="S500_Rotor_4" type="continuous">
    <origin xyz="-0.1645114 0.1633951 0.0733079" rpy="-0.0004304 0.1146026 -0.6588721"/>
    <parent link="World"/>
    <child link="Rotors_Rotor_4"/>
    <axis xyz="0. 0. 1."/>
  </joint>
  <link name="Link_1">
    <inertial>
      <origin xyz="0.0091162 0.0029992 0.0984083" rpy="0. 0. 0."/>
      <mass value="0.001"/>
      <inertia ixx="0.0000042" ixy="0." ixz="0.000002" iyy="0.0000052" iyz="-0." izz="0.0000011"/>
    </inertial>
    <visual>
      <origin xyz="-0.0103607 0.0504518 0.0023 " rpy="-1.5707964 -0. -2.9525185"/>
      <geometry>
        <mesh filename="file:///home/yubinkim/workspace/mtrl_am/file:/home/yubinkim/workspace/crazyflie_FTC/source/crazyflie_FTC/crazyflie_FTC/tasks/direct/crazyflie_ftc/models/meshes/Link_1_FR12_S101_FR12_S101.obj" scale="1. 1. 1."/>
      </geometry>
    </visual>
    <visual>
      <origin xyz="-0.0006813 -0.0001304 0.005 " rpy="-1.5707964 0. 0.0000002"/>
      <geometry>
        <mesh filename="file:///home/yubinkim/workspace/mtrl_am/file:/home/yubinkim/workspace/crazyflie_FTC/source/crazyflie_FTC/crazyflie_FTC/tasks/direct/crazyflie_ftc/models/meshes/Link_1_HN13_N105_HN13_N105.obj" scale="1. 1. 1."/>
      </geometry>
    </visual>
    <visual>
      <origin xyz="-0.0006813 -0.0001304 0.0263 " rpy="-0.1890743 1.5707964 0. "/>
      <geometry>
        <mesh filename="file:///home/yubinkim/workspace/mtrl_am/file:/home/yubinkim/workspace/crazyflie_FTC/source/crazyflie_FTC/crazyflie_FTC/tasks/direct/crazyflie_ftc/models/meshes/Link_1_FR13_H101_FR13_H101.obj" scale="1. 1. 1."/>
      </geometry>
    </visual>
    <collision>
      <origin xyz="-0.0103607 0.0504518 0.0023 " rpy="-1.5707964 -0. -2.9525185"/>
      <geometry>
        <mesh filename="file:///home/yubinkim/workspace/mtrl_am/file:/home/yubinkim/workspace/crazyflie_FTC/source/crazyflie_FTC/crazyflie_FTC/tasks/direct/crazyflie_ftc/models/meshes/Link_1_FR12_S101_FR12_S101.obj" scale="1. 1. 1."/>
      </geometry>
    </collision>
    <collision>
      <origin xyz="-0.0006813 -0.0001304 0.005 " rpy="-1.5707964 0. 0.0000002"/>
      <geometry>
        <mesh filename="file:///home/yubinkim/workspace/mtrl_am/file:/home/yubinkim/workspace/crazyflie_FTC/source/crazyflie_FTC/crazyflie_FTC/tasks/direct/crazyflie_ftc/models/meshes/Link_1_HN13_N105_HN13_N105.obj" scale="1. 1. 1."/>
      </geometry>
    </collision>
    <collision>
      <origin xyz="-0.0006813 -0.0001304 0.0263 " rpy="-0.1890743 1.5707964 0. "/>
      <geometry>
        <mesh filename="file:///home/yubinkim/workspace/mtrl_am/file:/home/yubinkim/workspace/crazyflie_FTC/source/crazyflie_FTC/crazyflie_FTC/tasks/direct/crazyflie_ftc/models/meshes/Link_1_FR13_H101_FR13_H101.obj" scale="1. 1. 1."/>
      </geometry>
    </collision>
  </link>
  <link name="Link_2">
    <inertial>
      <origin xyz="0.1854126 0.0075959 0.1283649" rpy="0. 0. 0."/>
      <mass value="0.001"/>
      <inertia ixx="0.0000075" ixy="0." ixz="0.0000003" iyy="0.0000075" iyz="-0." izz="0.0000001"/>
    </inertial>
    <visual>
      <origin xyz="0.278 0. 0.0183063" rpy="1.4209108 1.5707961 -1.7206819"/>
      <geometry>
        <mesh filename="file:///home/yubinkim/workspace/mtrl_am/file:/home/yubinkim/workspace/crazyflie_FTC/source/crazyflie_FTC/crazyflie_FTC/tasks/direct/crazyflie_ftc/models/meshes/Link_2_Part_1_Part_1.obj" scale="1. 1. 1."/>
      </geometry>
    </visual>
    <visual>
      <origin xyz="0. 0. 0.0183063" rpy="-2.9917066 -1.5707961 1.4209104"/>
      <geometry>
        <mesh filename="file:///home/yubinkim/workspace/mtrl_am/file:/home/yubinkim/workspace/crazyflie_FTC/source/crazyflie_FTC/crazyflie_FTC/tasks/direct/crazyflie_ftc/models/meshes/Link_2_FR12_H101_FR12_H101.obj" scale="1. 1. 1."/>
      </geometry>
    </visual>
    <visual>
      <origin xyz="0.028 0. 0.0183063" rpy="-2.9917066 -1.5707961 1.4209104"/>
      <geometry>
        <mesh filename="file:///home/yubinkim/workspace/mtrl_am/file:/home/yubinkim/workspace/crazyflie_FTC/source/crazyflie_FTC/crazyflie_FTC/tasks/direct/crazyflie_ftc/models/meshes/Link_2_Part_1_01_Part_1.obj" scale="1. 1. 1."/>
      </geometry>
    </visual>
    <visual>
      <origin xyz="0.2975 -0.01725 0.0183063" rpy="-1.7206818 1.5707961 -1.7206818"/>
      <geometry>
        <mesh filename="file:///home/yubinkim/workspace/mtrl_am/file:/home/yubinkim/workspace/crazyflie_FTC/source/crazyflie_FTC/crazyflie_FTC/tasks/direct/crazyflie_ftc/models/meshes/Link_2_FR12_E170_FR12_E170.obj" scale="1. 1. 1."/>
      </geometry>
    </visual>
    <visual>
      <origin xyz="0.028 0. 0.0183063" rpy="1.720682 -1.5707961 1.4209106"/>
      <geometry>
        <mesh filename="file:///home/yubinkim/workspace/mtrl_am/file:/home/yubinkim/workspace/crazyflie_FTC/source/crazyflie_FTC/crazyflie_FTC/tasks/direct/crazyflie_ftc/models/meshes/Link_2_Part_1_02_Part_1.obj" scale="1. 1. 1."/>
      </geometry>
    </visual>
    <visual>
      <origin xyz="0.2975 0. 0.0183063" rpy="1.4209107 1.5707961 -1.7206819"/>
      <geometry>
        <mesh filename="file:///home/yubinkim/workspace/mtrl_am/file:/home/yubinkim/workspace/crazyflie_FTC/source/crazyflie_FTC/crazyflie_FTC/tasks/direct/crazyflie_ftc/models/meshes/Link_2_FR12_S101_FR12_S101.obj" scale="1. 1. 1."/>
      </geometry>
    </visual>
    <collision>
      <origin xyz="0.278 0. 0.0183063" rpy="1.4209108 1.5707961 -1.7206819"/>
      <geometry>
        <mesh filename="file:///home/yubinkim/workspace/mtrl_am/file:/home/yubinkim/workspace/crazyflie_FTC/source/crazyflie_FTC/crazyflie_FTC/tasks/direct/crazyflie_ftc/models/meshes/Link_2_Part_1_Part_1.obj" scale="1. 1. 1."/>
      </geometry>
    </collision>
    <collision>
      <origin xyz="0. 0. 0.0183063" rpy="-2.9917066 -1.5707961 1.4209104"/>
      <geometry>
        <mesh filename="file:///home/yubinkim/workspace/mtrl_am/file:/home/yubinkim/workspace/crazyflie_FTC/source/crazyflie_FTC/crazyflie_FTC/tasks/direct/crazyflie_ftc/models/meshes/Link_2_FR12_H101_FR12_H101.obj" scale="1. 1. 1."/>
      </geometry>
    </collision>
    <collision>
      <origin xyz="0.028 0. 0.0183063" rpy="-2.9917066 -1.5707961 1.4209104"/>
      <geometry>
        <mesh filename="file:///home/yubinkim/workspace/mtrl_am/file:/home/yubinkim/workspace/crazyflie_FTC/source/crazyflie_FTC/crazyflie_FTC/tasks/direct/crazyflie_ftc/models/meshes/Link_2_Part_1_01_Part_1.obj" scale="1. 1. 1."/>
      </geometry>
    </collision>
    <collision>
      <origin xyz="0.2975 -0.01725 0.0183063" rpy="-1.7206818 1.5707961 -1.7206818"/>
      <geometry>
        <mesh filename="file:///home/yubinkim/workspace/mtrl_am/file:/home/yubinkim/workspace/crazyflie_FTC/source/crazyflie_FTC/crazyflie_FTC/tasks/direct/crazyflie_ftc/models/meshes/Link_2_FR12_E170_FR12_E170.obj" scale="1. 1. 1."/>
      </geometry>
    </collision>
    <collision>
      <origin xyz="0.028 0. 0.0183063" rpy="1.720682 -1.5707961 1.4209106"/>
      <geometry>
        <mesh filename="file:///home/yubinkim/workspace/mtrl_am/file:/home/yubinkim/workspace/crazyflie_FTC/source/crazyflie_FTC/crazyflie_FTC/tasks/direct/crazyflie_ftc/models/meshes/Link_2_Part_1_02_Part_1.obj" scale="1. 1. 1."/>
      </geometry>
    </collision>
    <collision>
      <origin xyz="0.2975 0. 0.0183063" rpy="1.4209107 1.5707961 -1.7206819"/>
      <geometry>
        <mesh filename="file:///home/yubinkim/workspace/mtrl_am/file:/home/yubinkim/workspace/crazyflie_FTC/source/crazyflie_FTC/crazyflie_FTC/tasks/direct/crazyflie_ftc/models/meshes/Link_2_FR12_S101_FR12_S101.obj" scale="1. 1. 1."/>
      </geometry>
    </collision>
  </link>
  <link name="Link_3">
    <inertial>
      <origin xyz="0. 0. 0." rpy="0. 0. 0."/>
      <mass value="0.002"/>
      <inertia ixx="0.001" ixy="0." ixz="0." iyy="0.001" iyz="0." izz="0.001"/>
    </inertial>
    <visual>
      <origin xyz="-0.0190546 0.0000002 0.0183063" rpy="-2.8905127 -1.5707961 1.3198416"/>
      <geometry>
        <mesh filename="file:///home/yubinkim/workspace/mtrl_am/file:/home/yubinkim/workspace/crazyflie_FTC/source/crazyflie_FTC/crazyflie_FTC/tasks/direct/crazyflie_ftc/models/meshes/Link_3_FR12_E171_FR12_E171.obj" scale="1. 1. 1."/>
      </geometry>
    </visual>
    <collision>
      <origin xyz="-0.0190546 0.0000002 0.0183063" rpy="-2.8905127 -1.5707961 1.3198416"/>
      <geometry>
        <mesh filename="file:///home/yubinkim/workspace/mtrl_am/file:/home/yubinkim/workspace/crazyflie_FTC/source/crazyflie_FTC/crazyflie_FTC/tasks/direct/crazyflie_ftc/models/meshes/Link_3_FR12_E171_FR12_E171.obj" scale="1. 1. 1."/>
      </geometry>
    </collision>
  </link>
  <link name="Motor_1">
    <inertial>
      <origin xyz="0.0007071 0.0014008 0.0837471" rpy="0. 0. 0."/>
      <mass value="0.1852"/>
      <inertia ixx="0.0000838" ixy="0." ixz="0." iyy="0.0000694" iyz="0." izz="0.0000694"/>
    </inertial>
    <visual>
      <origin xyz="0.0007071 0.0014008 0.0837471" rpy="0. 1.5707964 0. "/>
      <geometry>
        <mesh filename="file:///home/yubinkim/workspace/mtrl_am/file:/home/yubinkim/workspace/crazyflie_FTC/source/crazyflie_FTC/crazyflie_FTC/tasks/direct/crazyflie_ftc/models/meshes/Motor_1_DC13_C00_DUMMY_DC13_C00_DUMMY.obj" scale="1. 1. 1."/>
      </geometry>
    </visual>
    <collision>
      <origin xyz="0.0007071 0.0014008 0.0837471" rpy="0. 1.5707964 0. "/>
      <geometry>
        <mesh filename="file:///home/yubinkim/workspace/mtrl_am/file:/home/yubinkim/workspace/crazyflie_FTC/source/crazyflie_FTC/crazyflie_FTC/tasks/direct/crazyflie_ftc/models/meshes/Motor_1_DC13_C00_DUMMY_DC13_C00_DUMMY.obj" scale="1. 1. 1."/>
      </geometry>
    </collision>
  </link>
  <link name="Motor_2">
    <inertial>
      <origin xyz="0.0267071 0.0014008 0.1352471" rpy="0. 0. 0."/>
      <mass value="0.0821"/>
      <inertia ixx="0.0000221" ixy="-0." ixz="-0." iyy="0.0000199" iyz="0.0000002" izz="0.0000128"/>
    </inertial>
    <visual>
      <origin xyz="0.0262071 0.0087695 0.1359971" rpy="-3.1415927 -1.4185356 1.5707963"/>
      <geometry>
        <mesh filename="file:///home/yubinkim/workspace/mtrl_am/file:/home/yubinkim/workspace/crazyflie_FTC/source/crazyflie_FTC/crazyflie_FTC/tasks/direct/crazyflie_ftc/models/meshes/Motor_2_DUMMY_DC12_DUMMY_DC12.obj" scale="1. 1. 1."/>
      </geometry>
    </visual>
    <collision>
      <origin xyz="0.0262071 0.0087695 0.1359971" rpy="-3.1415927 -1.4185356 1.5707963"/>
      <geometry>
        <mesh filename="file:///home/yubinkim/workspace/mtrl_am/file:/home/yubinkim/workspace/crazyflie_FTC/source/crazyflie_FTC/crazyflie_FTC/tasks/direct/crazyflie_ftc/models/meshes/Motor_2_DUMMY_DC12_DUMMY_DC12.obj" scale="1. 1. 1."/>
      </geometry>
    </collision>
  </link>
  <link name="Motor_3">
    <inertial>
      <origin xyz="0.3241998 0.0014008 0.1592471" rpy="0. 0. 0."/>
      <mass value="0.05723"/>
      <inertia ixx="0.0000154" ixy="0.0000001" ixz="-0." iyy="0.0000132" iyz="0." izz="0.000009"/>
    </inertial>
    <visual>
      <origin xyz="0.3241998 0.0014008 0.1592471" rpy="1.5707963 -0. 3.1415927"/>
      <geometry>
        <mesh filename="file:///home/yubinkim/workspace/mtrl_am/file:/home/yubinkim/workspace/crazyflie_FTC/source/crazyflie_FTC/crazyflie_FTC/tasks/direct/crazyflie_ftc/models/meshes/Motor_3_DUMMY_DC12_DUMMY_DC12.obj" scale="1. 1. 1."/>
      </geometry>
    </visual>
    <collision>
      <origin xyz="0.3241998 0.0014008 0.1592471" rpy="1.5707963 -0. 3.1415927"/>
      <geometry>
        <mesh filename="file:///home/yubinkim/workspace/mtrl_am/file:/home/yubinkim/workspace/crazyflie_FTC/source/crazyflie_FTC/crazyflie_FTC/tasks/direct/crazyflie_ftc/models/meshes/Motor_3_DUMMY_DC12_DUMMY_DC12.obj" scale="1. 1. 1."/>
      </geometry>
    </collision>
  </link>
  <link name="Rotors_Rotor_1">
    <visual>
      <origin xyz="0.0013679 0.0000473 -0.0031849" rpy="-3.126844 -0.0091888 -0.9175152"/>
      <geometry>
        <mesh filename="file:///home/yubinkim/workspace/mtrl_am/file:/home/yubinkim/workspace/crazyflie_FTC/source/crazyflie_FTC/crazyflie_FTC/tasks/direct/crazyflie_ftc/models/meshes/Rotors_Rotor_1_Rotor_Black.obj" scale="1. 1. 1."/>
      </geometry>
    </visual>
  </link>
  <link name="Rotors_Rotor_2">
    <visual>
      <origin xyz="0.0012231 -0.0003222 -0.0045665" rpy="3.1242604 0.0003704 1.569266 "/>
      <geometry>
        <mesh filename="file:///home/yubinkim/workspace/mtrl_am/file:/home/yubinkim/workspace/crazyflie_FTC/source/crazyflie_FTC/crazyflie_FTC/tasks/direct/crazyflie_ftc/models/meshes/Rotors_Rotor_2_Rotor_Blue.obj" scale="1. 1. 1."/>
      </geometry>
    </visual>
  </link>
  <link name="Rotors_Rotor_3">
    <visual>
      <origin xyz="0.0016114 -0.0001883 -0.0098847" rpy="-3.127992 -0.0108211 -1.0238825"/>
      <geometry>
        <mesh filename="file:///home/yubinkim/workspace/mtrl_am/file:/home/yubinkim/workspace/crazyflie_FTC/source/crazyflie_FTC/crazyflie_FTC/tasks/direct/crazyflie_ftc/models/meshes/Rotors_Rotor_3_Rotor_Black.obj" scale="1. 1. 1."/>
      </geometry>
    </visual>
  </link>
  <link name="Rotors_Rotor_4">
    <visual>
      <origin xyz="0.001229 0.0007678 -0.0085065" rpy="3.127839 0.0105435 3.1291413"/>
      <geometry>
        <mesh filename="file:///home/yubinkim/workspace/mtrl_am/file:/home/yubinkim/workspace/crazyflie_FTC/source/crazyflie_FTC/crazyflie_FTC/tasks/direct/crazyflie_ftc/models/meshes/Rotors_Rotor_4_Rotor_Blue.obj" scale="1. 1. 1."/>
      </geometry>
    </visual>
  </link>
  <link name="World">
    <visual>
      <origin xyz="0.0441702 0. -0.0455247" rpy="-1.5707964 -0.0000001 1.5707964"/>
      <geometry>
        <mesh filename="file:///home/yubinkim/workspace/mtrl_am/file:/home/yubinkim/workspace/crazyflie_FTC/source/crazyflie_FTC/crazyflie_FTC/tasks/direct/crazyflie_ftc/models/meshes/Base_Battery_Plate_Battery_Plate.obj" scale="1. 1. 1."/>
      </geometry>
    </visual>
    <visual>
      <origin xyz="-0.0463155 -0.0463155 -0.1499999" rpy="1.5707964 -0.0000001 0.7853982"/>
      <geometry>
        <mesh filename="file:///home/yubinkim/workspace/mtrl_am/file:/home/yubinkim/workspace/crazyflie_FTC/source/crazyflie_FTC/crazyflie_FTC/tasks/direct/crazyflie_ftc/models/meshes/Base_Leg_Leg.obj" scale="1. 1. 1."/>
      </geometry>
    </visual>
    <visual>
      <origin xyz="0.1648932 0.1648932 0.0512468" rpy="0.0741836 0.0739804 -1.5680498"/>
      <geometry>
        <mesh filename="file:///home/yubinkim/workspace/mtrl_am/file:/home/yubinkim/workspace/crazyflie_FTC/source/crazyflie_FTC/crazyflie_FTC/tasks/direct/crazyflie_ftc/models/meshes/Base_Part_1_Part_1.obj" scale="1. 1. 1."/>
      </geometry>
    </visual>
    <visual>
      <origin xyz="0.0007071 0.0007071 0.0600001" rpy="1.5707963 -0.0000001 1.5707964"/>
      <geometry>
        <mesh filename="file:///home/yubinkim/workspace/mtrl_am/file:/home/yubinkim/workspace/crazyflie_FTC/source/crazyflie_FTC/crazyflie_FTC/tasks/direct/crazyflie_ftc/models/meshes/Base_Part_1_01_Part_1.obj" scale="1. 1. 1."/>
      </geometry>
    </visual>
    <visual>
      <origin xyz="0.0007071 0.0007071 0.0835001" rpy="3.1415925 0.0000001 -3.1415927"/>
      <geometry>
        <mesh filename="file:///home/yubinkim/workspace/mtrl_am/file:/home/yubinkim/workspace/crazyflie_FTC/source/crazyflie_FTC/crazyflie_FTC/tasks/direct/crazyflie_ftc/models/meshes/Base_FR13_S101_FR13_S101.obj" scale="1. 1. 1."/>
      </geometry>
    </visual>
    <visual>
      <origin xyz="0.0420729 -0.0420729 0.0200001" rpy="1.5707963 -0. 2.3561945"/>
      <geometry>
        <mesh filename="file:///home/yubinkim/workspace/mtrl_am/file:/home/yubinkim/workspace/crazyflie_FTC/source/crazyflie_FTC/crazyflie_FTC/tasks/direct/crazyflie_ftc/models/meshes/Base_Arm_Blue_Arm_Blue.obj" scale="1. 1. 1."/>
      </geometry>
    </visual>
    <visual>
      <origin xyz="0.0463155 -0.0463155 -0.1499999" rpy="1.5707963 -0. 2.3561945"/>
      <geometry>
        <mesh filename="file:///home/yubinkim/workspace/mtrl_am/file:/home/yubinkim/workspace/crazyflie_FTC/source/crazyflie_FTC/crazyflie_FTC/tasks/direct/crazyflie_ftc/models/meshes/Leg_01_Leg.obj" scale="1. 1. 1."/>
      </geometry>
    </visual>
    <visual>
      <origin xyz="0.0791702 0. -0.0445247" rpy="1.5707963 -0.0000001 1.5707964"/>
      <geometry>
        <mesh filename="file:///home/yubinkim/workspace/mtrl_am/file:/home/yubinkim/workspace/crazyflie_FTC/source/crazyflie_FTC/crazyflie_FTC/tasks/direct/crazyflie_ftc/models/meshes/Base_Battery_Plate_Support_Battery_Plate_Support.obj" scale="1. 1. 1."/>
      </geometry>
    </visual>
    <visual>
      <origin xyz="0.024 -0.03 -0.0129999" rpy="-1.5707963 0.0000001 -1.5707964"/>
      <geometry>
        <mesh filename="file:///home/yubinkim/workspace/mtrl_am/file:/home/yubinkim/workspace/crazyflie_FTC/source/crazyflie_FTC/crazyflie_FTC/tasks/direct/crazyflie_ftc/models/meshes/Base_Rail_Support_Rail_Support.obj" scale="1. 1. 1."/>
      </geometry>
    </visual>
    <visual>
      <origin xyz="-0.1648932 -0.1648932 0.0512467" rpy="0.0741835 0.0739801 1.573543 "/>
      <geometry>
        <mesh filename="file:///home/yubinkim/workspace/mtrl_am/file:/home/yubinkim/workspace/crazyflie_FTC/source/crazyflie_FTC/crazyflie_FTC/tasks/direct/crazyflie_ftc/models/meshes/Base_Part_1_02_Part_1.obj" scale="1. 1. 1."/>
      </geometry>
    </visual>
    <visual>
      <origin xyz="0. 0. 0.0215001" rpy="-1.5707963 -0.0000001 0.7853982"/>
      <geometry>
        <mesh filename="file:///home/yubinkim/workspace/mtrl_am/file:/home/yubinkim/workspace/crazyflie_FTC/source/crazyflie_FTC/crazyflie_FTC/tasks/direct/crazyflie_ftc/models/meshes/Base_Top_Plate_Top_Plate.obj" scale="1. 1. 1."/>
      </geometry>
    </visual>
    <visual>
      <origin xyz="0.1648932 -0.1648932 0.0512468" rpy="-0.0741834 -0.0739803 0.0027466"/>
      <geometry>
        <mesh filename="file:///home/yubinkim/workspace/mtrl_am/file:/home/yubinkim/workspace/crazyflie_FTC/source/crazyflie_FTC/crazyflie_FTC/tasks/direct/crazyflie_ftc/models/meshes/Part_1_03_Part_1.obj" scale="1. 1. 1."/>
      </geometry>
    </visual>
    <visual>
      <origin xyz="0.1649006 -0.1649006 0.0511473" rpy="-0.0910873 -0.0517371 0.2702259"/>
      <geometry>
        <mesh filename="file:///home/yubinkim/workspace/mtrl_am/file:/home/yubinkim/workspace/crazyflie_FTC/source/crazyflie_FTC/crazyflie_FTC/tasks/direct/crazyflie_ftc/models/meshes/Base_Part_2_Part_2.obj" scale="1. 1. 1."/>
      </geometry>
    </visual>
    <visual>
      <origin xyz="0.1649006 0.1649006 0.0511473" rpy="0.0618769 -0.0845377 0.1523763"/>
      <geometry>
        <mesh filename="file:///home/yubinkim/workspace/mtrl_am/file:/home/yubinkim/workspace/crazyflie_FTC/source/crazyflie_FTC/crazyflie_FTC/tasks/direct/crazyflie_ftc/models/meshes/Part_2_01_Part_2.obj" scale="1. 1. 1."/>
      </geometry>
    </visual>
    <visual>
      <origin xyz="0.0463155 0.0463155 -0.1499999" rpy="1.5707963 0.0000001 -2.3561945"/>
      <geometry>
        <mesh filename="file:///home/yubinkim/workspace/mtrl_am/file:/home/yubinkim/workspace/crazyflie_FTC/source/crazyflie_FTC/crazyflie_FTC/tasks/direct/crazyflie_ftc/models/meshes/Leg_02_Leg.obj" scale="1. 1. 1."/>
      </geometry>
    </visual>
    <visual>
      <origin xyz="-0.024 -0.03 -0.0129999" rpy="2.0532982 -1.5707963 -2.0532982"/>
      <geometry>
        <mesh filename="file:///home/yubinkim/workspace/mtrl_am/file:/home/yubinkim/workspace/crazyflie_FTC/source/crazyflie_FTC/crazyflie_FTC/tasks/direct/crazyflie_ftc/models/meshes/Base_Rail_Support_Grommet_Rail_Support_Grommet.obj" scale="1. 1. 1."/>
      </geometry>
    </visual>
    <visual>
      <origin xyz="-0.0420728 -0.0420729 0.0200001" rpy="1.5707964 -0.0000001 0.7853982"/>
      <geometry>
        <mesh filename="file:///home/yubinkim/workspace/mtrl_am/file:/home/yubinkim/workspace/crazyflie_FTC/source/crazyflie_FTC/crazyflie_FTC/tasks/direct/crazyflie_ftc/models/meshes/Base_Arm_White_Arm_White.obj" scale="1. 1. 1."/>
      </geometry>
    </visual>
    <visual>
      <origin xyz="0.024 -0.03 -0.0129999" rpy="1.0882958 1.5707963 1.0882958"/>
      <geometry>
        <mesh filename="file:///home/yubinkim/workspace/mtrl_am/file:/home/yubinkim/workspace/crazyflie_FTC/source/crazyflie_FTC/crazyflie_FTC/tasks/direct/crazyflie_ftc/models/meshes/Rail_Support_Grommet_01_Rail_Support_Grommet.obj" scale="1. 1. 1."/>
      </geometry>
    </visual>
    <visual>
      <origin xyz="-0.024 -0.03 -0.0129999" rpy="-1.5707964 -0.0000001 1.5707964"/>
      <geometry>
        <mesh filename="file:///home/yubinkim/workspace/mtrl_am/file:/home/yubinkim/workspace/crazyflie_FTC/source/crazyflie_FTC/crazyflie_FTC/tasks/direct/crazyflie_ftc/models/meshes/Rail_Support_01_Rail_Support.obj" scale="1. 1. 1."/>
      </geometry>
    </visual>
    <visual>
      <origin xyz="0.0565686 0.0353553 0.0200001" rpy="0. -0.0000001 0.7853982"/>
      <geometry>
        <mesh filename="file:///home/yubinkim/workspace/mtrl_am/file:/home/yubinkim/workspace/crazyflie_FTC/source/crazyflie_FTC/crazyflie_FTC/tasks/direct/crazyflie_ftc/models/meshes/Part_1_04_Part_1.obj" scale="1. 1. 1."/>
      </geometry>
    </visual>
    <visual>
      <origin xyz="-0.024 0.03 -0.0129999" rpy="1.0882958 1.5707963 1.0882958"/>
      <geometry>
        <mesh filename="file:///home/yubinkim/workspace/mtrl_am/file:/home/yubinkim/workspace/crazyflie_FTC/source/crazyflie_FTC/crazyflie_FTC/tasks/direct/crazyflie_ftc/models/meshes/Rail_Support_Grommet_02_Rail_Support_Grommet.obj" scale="1. 1. 1."/>
      </geometry>
    </visual>
    <visual>
      <origin xyz="-0.0339411 -0.0551543 0.0200001" rpy="0. -0.0000001 0.7853982"/>
      <geometry>
        <mesh filename="file:///home/yubinkim/workspace/mtrl_am/file:/home/yubinkim/workspace/crazyflie_FTC/source/crazyflie_FTC/crazyflie_FTC/tasks/direct/crazyflie_ftc/models/meshes/Part_1_05_Part_1.obj" scale="1. 1. 1."/>
      </geometry>
    </visual>
    <visual>
      <origin xyz="0.0353553 0.0565685 0.0200001" rpy="0.0000001 -0.0000001 0. "/>
      <geometry>
        <mesh filename="file:///home/yubinkim/workspace/mtrl_am/file:/home/yubinkim/workspace/crazyflie_FTC/source/crazyflie_FTC/crazyflie_FTC/tasks/direct/crazyflie_ftc/models/meshes/Part_1_06_Part_1.obj" scale="1. 1. 1."/>
      </geometry>
    </visual>
    <visual>
      <origin xyz="0.0565686 -0.0339411 0.0200001" rpy="0.0000001 0. -0.7853981"/>
      <geometry>
        <mesh filename="file:///home/yubinkim/workspace/mtrl_am/file:/home/yubinkim/workspace/crazyflie_FTC/source/crazyflie_FTC/crazyflie_FTC/tasks/direct/crazyflie_ftc/models/meshes/Part_1_07_Part_1.obj" scale="1. 1. 1."/>
      </geometry>
    </visual>
    <visual>
      <origin xyz="-0.1649006 -0.1649006 0.0511473" rpy="-0.041916 0.095993 0.372916"/>
      <geometry>
        <mesh filename="file:///home/yubinkim/workspace/mtrl_am/file:/home/yubinkim/workspace/crazyflie_FTC/source/crazyflie_FTC/crazyflie_FTC/tasks/direct/crazyflie_ftc/models/meshes/Part_2_02_Part_2.obj" scale="1. 1. 1."/>
      </geometry>
    </visual>
    <visual>
      <origin xyz="0.0091702 0. -0.0445247" rpy="1.5707963 -0.0000001 1.5707964"/>
      <geometry>
        <mesh filename="file:///home/yubinkim/workspace/mtrl_am/file:/home/yubinkim/workspace/crazyflie_FTC/source/crazyflie_FTC/crazyflie_FTC/tasks/direct/crazyflie_ftc/models/meshes/Battery_Plate_Support_01_Battery_Plate_Support.obj" scale="1. 1. 1."/>
      </geometry>
    </visual>
    <visual>
      <origin xyz="0. 0.03 -0.0129999" rpy="1.570811 -1.5671672 -1.570811 "/>
      <geometry>
        <mesh filename="file:///home/yubinkim/workspace/mtrl_am/file:/home/yubinkim/workspace/crazyflie_FTC/source/crazyflie_FTC/crazyflie_FTC/tasks/direct/crazyflie_ftc/models/meshes/Base_Rail_Rail.obj" scale="1. 1. 1."/>
      </geometry>
    </visual>
    <visual>
      <origin xyz="-0.0551543 0.0353553 0.0200001" rpy="0.0000001 -0.0000001 0. "/>
      <geometry>
        <mesh filename="file:///home/yubinkim/workspace/mtrl_am/file:/home/yubinkim/workspace/crazyflie_FTC/source/crazyflie_FTC/crazyflie_FTC/tasks/direct/crazyflie_ftc/models/meshes/Part_1_08_Part_1.obj" scale="1. 1. 1."/>
      </geometry>
    </visual>
    <visual>
      <origin xyz="-0.1649006 0.1649006 0.0511473" rpy="0.0133503 0.1038684 -0.6573337"/>
      <geometry>
        <mesh filename="file:///home/yubinkim/workspace/mtrl_am/file:/home/yubinkim/workspace/crazyflie_FTC/source/crazyflie_FTC/crazyflie_FTC/tasks/direct/crazyflie_ftc/models/meshes/Part_2_03_Part_2.obj" scale="1. 1. 1."/>
      </geometry>
    </visual>
    <visual>
      <origin xyz="-0.0339411 0.0565685 0.0200001" rpy="0. -0.0000001 0.7853982"/>
      <geometry>
        <mesh filename="file:///home/yubinkim/workspace/mtrl_am/file:/home/yubinkim/workspace/crazyflie_FTC/source/crazyflie_FTC/crazyflie_FTC/tasks/direct/crazyflie_ftc/models/meshes/Part_1_09_Part_1.obj" scale="1. 1. 1."/>
      </geometry>
    </visual>
    <visual>
      <origin xyz="-0.024 0.03 -0.0129999" rpy="-1.5707963 0.0000001 -1.5707964"/>
      <geometry>
        <mesh filename="file:///home/yubinkim/workspace/mtrl_am/file:/home/yubinkim/workspace/crazyflie_FTC/source/crazyflie_FTC/crazyflie_FTC/tasks/direct/crazyflie_ftc/models/meshes/Rail_Support_02_Rail_Support.obj" scale="1. 1. 1."/>
      </geometry>
    </visual>
    <visual>
      <origin xyz="0.0420729 0.0420729 0.0200001" rpy="1.5707963 0.0000001 -2.3561945"/>
      <geometry>
        <mesh filename="file:///home/yubinkim/workspace/mtrl_am/file:/home/yubinkim/workspace/crazyflie_FTC/source/crazyflie_FTC/crazyflie_FTC/tasks/direct/crazyflie_ftc/models/meshes/Arm_Blue_01_Arm_Blue.obj" scale="1. 1. 1."/>
      </geometry>
    </visual>
    <visual>
      <origin xyz="-0.1648932 0.1648932 0.0512468" rpy="-0.0741836 -0.0739802 -3.1388462"/>
      <geometry>
        <mesh filename="file:///home/yubinkim/workspace/mtrl_am/file:/home/yubinkim/workspace/crazyflie_FTC/source/crazyflie_FTC/crazyflie_FTC/tasks/direct/crazyflie_ftc/models/meshes/Part_1_10_Part_1.obj" scale="1. 1. 1."/>
      </geometry>
    </visual>
    <visual>
      <origin xyz="-0.0551543 -0.0339411 0.0200001" rpy="0.0000001 -0.0000001 0. "/>
      <geometry>
        <mesh filename="file:///home/yubinkim/workspace/mtrl_am/file:/home/yubinkim/workspace/crazyflie_FTC/source/crazyflie_FTC/crazyflie_FTC/tasks/direct/crazyflie_ftc/models/meshes/Part_1_11_Part_1.obj" scale="1. 1. 1."/>
      </geometry>
    </visual>
    <visual>
      <origin xyz="-0.0463155 0.0463155 -0.1499999" rpy="1.5707965 0. -0.7853981"/>
      <geometry>
        <mesh filename="file:///home/yubinkim/workspace/mtrl_am/file:/home/yubinkim/workspace/crazyflie_FTC/source/crazyflie_FTC/crazyflie_FTC/tasks/direct/crazyflie_ftc/models/meshes/Leg_03_Leg.obj" scale="1. 1. 1."/>
      </geometry>
    </visual>
    <visual>
      <origin xyz="0.024 0.03 -0.0129999" rpy="-1.5707964 -0.0000001 1.5707964"/>
      <geometry>
        <mesh filename="file:///home/yubinkim/workspace/mtrl_am/file:/home/yubinkim/workspace/crazyflie_FTC/source/crazyflie_FTC/crazyflie_FTC/tasks/direct/crazyflie_ftc/models/meshes/Rail_Support_03_Rail_Support.obj" scale="1. 1. 1."/>
      </geometry>
    </visual>
    <visual>
      <origin xyz="0. 0. 0.0000001" rpy="1.5707964 -0.0000001 0. "/>
      <geometry>
        <mesh filename="file:///home/yubinkim/workspace/mtrl_am/file:/home/yubinkim/workspace/crazyflie_FTC/source/crazyflie_FTC/crazyflie_FTC/tasks/direct/crazyflie_ftc/models/meshes/Base_Bottom_Plate_Bottom_Plate.obj" scale="1. 1. 1."/>
      </geometry>
    </visual>
    <visual>
      <origin xyz="0.024 0.03 -0.0129999" rpy="2.0532982 -1.5707963 -2.0532982"/>
      <geometry>
        <mesh filename="file:///home/yubinkim/workspace/mtrl_am/file:/home/yubinkim/workspace/crazyflie_FTC/source/crazyflie_FTC/crazyflie_FTC/tasks/direct/crazyflie_ftc/models/meshes/Rail_Support_Grommet_03_Rail_Support_Grommet.obj" scale="1. 1. 1."/>
      </geometry>
    </visual>
    <visual>
      <origin xyz="-0.0420728 0.0420729 0.0200001" rpy="1.5707965 0. -0.7853981"/>
      <geometry>
        <mesh filename="file:///home/yubinkim/workspace/mtrl_am/file:/home/yubinkim/workspace/crazyflie_FTC/source/crazyflie_FTC/crazyflie_FTC/tasks/direct/crazyflie_ftc/models/meshes/Arm_White_01_Arm_White.obj" scale="1. 1. 1."/>
      </geometry>
    </visual>
    <visual>
      <origin xyz="0.0353553 -0.0551543 0.0200001" rpy="0. -0.0000001 0.7853982"/>
      <geometry>
        <mesh filename="file:///home/yubinkim/workspace/mtrl_am/file:/home/yubinkim/workspace/crazyflie_FTC/source/crazyflie_FTC/crazyflie_FTC/tasks/direct/crazyflie_ftc/models/meshes/Part_1_12_Part_1.obj" scale="1. 1. 1."/>
      </geometry>
    </visual>
    <visual>
      <origin xyz="0. -0.03 -0.0129999" rpy="1.0882958 1.5707963 1.0882958"/>
      <geometry>
        <mesh filename="file:///home/yubinkim/workspace/mtrl_am/file:/home/yubinkim/workspace/crazyflie_FTC/source/crazyflie_FTC/crazyflie_FTC/tasks/direct/crazyflie_ftc/models/meshes/Rail_01_Rail.obj" scale="1. 1. 1."/>
      </geometry>
    </visual>
    <collision>
      <origin xyz="0.0441702 0. -0.0455247" rpy="-1.5707964 -0.0000001 1.5707964"/>
      <geometry>
        <mesh filename="file:///home/yubinkim/workspace/mtrl_am/file:/home/yubinkim/workspace/crazyflie_FTC/source/crazyflie_FTC/crazyflie_FTC/tasks/direct/crazyflie_ftc/models/meshes/Base_Battery_Plate_Battery_Plate.obj" scale="1. 1. 1."/>
      </geometry>
    </collision>
    <collision>
      <origin xyz="-0.0463155 -0.0463155 -0.1499999" rpy="1.5707964 -0.0000001 0.7853982"/>
      <geometry>
        <mesh filename="file:///home/yubinkim/workspace/mtrl_am/file:/home/yubinkim/workspace/crazyflie_FTC/source/crazyflie_FTC/crazyflie_FTC/tasks/direct/crazyflie_ftc/models/meshes/Base_Leg_Leg.obj" scale="1. 1. 1."/>
      </geometry>
    </collision>
    <collision>
      <origin xyz="0.1648932 0.1648932 0.0512468" rpy="0.0741836 0.0739804 -1.5680498"/>
      <geometry>
        <mesh filename="file:///home/yubinkim/workspace/mtrl_am/file:/home/yubinkim/workspace/crazyflie_FTC/source/crazyflie_FTC/crazyflie_FTC/tasks/direct/crazyflie_ftc/models/meshes/Base_Part_1_Part_1.obj" scale="1. 1. 1."/>
      </geometry>
    </collision>
    <collision>
      <origin xyz="0.0007071 0.0007071 0.0600001" rpy="1.5707963 -0.0000001 1.5707964"/>
      <geometry>
        <mesh filename="file:///home/yubinkim/workspace/mtrl_am/file:/home/yubinkim/workspace/crazyflie_FTC/source/crazyflie_FTC/crazyflie_FTC/tasks/direct/crazyflie_ftc/models/meshes/Base_Part_1_01_Part_1.obj" scale="1. 1. 1."/>
      </geometry>
    </collision>
    <collision>
      <origin xyz="0.0007071 0.0007071 0.0835001" rpy="3.1415925 0.0000001 -3.1415927"/>
      <geometry>
        <mesh filename="file:///home/yubinkim/workspace/mtrl_am/file:/home/yubinkim/workspace/crazyflie_FTC/source/crazyflie_FTC/crazyflie_FTC/tasks/direct/crazyflie_ftc/models/meshes/Base_FR13_S101_FR13_S101.obj" scale="1. 1. 1."/>
      </geometry>
    </collision>
    <collision>
      <origin xyz="0.0420729 -0.0420729 0.0200001" rpy="1.5707963 -0. 2.3561945"/>
      <geometry>
        <mesh filename="file:///home/yubinkim/workspace/mtrl_am/file:/home/yubinkim/workspace/crazyflie_FTC/source/crazyflie_FTC/crazyflie_FTC/tasks/direct/crazyflie_ftc/models/meshes/Base_Arm_Blue_Arm_Blue.obj" scale="1. 1. 1."/>
      </geometry>
    </collision>
    <collision>
      <origin xyz="0.0463155 -0.0463155 -0.1499999" rpy="1.5707963 -0. 2.3561945"/>
      <geometry>
        <mesh filename="file:///home/yubinkim/workspace/mtrl_am/file:/home/yubinkim/workspace/crazyflie_FTC/source/crazyflie_FTC/crazyflie_FTC/tasks/direct/crazyflie_ftc/models/meshes/Leg_01_Leg.obj" scale="1. 1. 1."/>
      </geometry>
    </collision>
    <collision>
      <origin xyz="0.0791702 0. -0.0445247" rpy="1.5707963 -0.0000001 1.5707964"/>
      <geometry>
        <mesh filename="file:///home/yubinkim/workspace/mtrl_am/file:/home/yubinkim/workspace/crazyflie_FTC/source/crazyflie_FTC/crazyflie_FTC/tasks/direct/crazyflie_ftc/models/meshes/Base_Battery_Plate_Support_Battery_Plate_Support.obj" scale="1. 1. 1."/>
      </geometry>
    </collision>
    <collision>
      <origin xyz="0.024 -0.03 -0.0129999" rpy="-1.5707963 0.0000001 -1.5707964"/>
      <geometry>
        <mesh filename="file:///home/yubinkim/workspace/mtrl_am/file:/home/yubinkim/workspace/crazyflie_FTC/source/crazyflie_FTC/crazyflie_FTC/tasks/direct/crazyflie_ftc/models/meshes/Base_Rail_Support_Rail_Support.obj" scale="1. 1. 1."/>
      </geometry>
    </collision>
    <collision>
      <origin xyz="-0.1648932 -0.1648932 0.0512467" rpy="0.0741835 0.0739801 1.573543 "/>
      <geometry>
        <mesh filename="file:///home/yubinkim/workspace/mtrl_am/file:/home/yubinkim/workspace/crazyflie_FTC/source/crazyflie_FTC/crazyflie_FTC/tasks/direct/crazyflie_ftc/models/meshes/Base_Part_1_02_Part_1.obj" scale="1. 1. 1."/>
      </geometry>
    </collision>
    <collision>
      <origin xyz="0. 0. 0.0215001" rpy="-1.5707963 -0.0000001 0.7853982"/>
      <geometry>
        <mesh filename="file:///home/yubinkim/workspace/mtrl_am/file:/home/yubinkim/workspace/crazyflie_FTC/source/crazyflie_FTC/crazyflie_FTC/tasks/direct/crazyflie_ftc/models/meshes/Base_Top_Plate_Top_Plate.obj" scale="1. 1. 1."/>
      </geometry>
    </collision>
    <collision>
      <origin xyz="0.1648932 -0.1648932 0.0512468" rpy="-0.0741834 -0.0739803 0.0027466"/>
      <geometry>
        <mesh filename="file:///home/yubinkim/workspace/mtrl_am/file:/home/yubinkim/workspace/crazyflie_FTC/source/crazyflie_FTC/crazyflie_FTC/tasks/direct/crazyflie_ftc/models/meshes/Part_1_03_Part_1.obj" scale="1. 1. 1."/>
      </geometry>
    </collision>
    <collision>
      <origin xyz="0.1649006 -0.1649006 0.0511473" rpy="-0.0910873 -0.0517371 0.2702259"/>
      <geometry>
        <mesh filename="file:///home/yubinkim/workspace/mtrl_am/file:/home/yubinkim/workspace/crazyflie_FTC/source/crazyflie_FTC/crazyflie_FTC/tasks/direct/crazyflie_ftc/models/meshes/Base_Part_2_Part_2.obj" scale="1. 1. 1."/>
      </geometry>
    </collision>
    <collision>
      <origin xyz="0.1649006 0.1649006 0.0511473" rpy="0.0618769 -0.0845377 0.1523763"/>
      <geometry>
        <mesh filename="file:///home/yubinkim/workspace/mtrl_am/file:/home/yubinkim/workspace/crazyflie_FTC/source/crazyflie_FTC/crazyflie_FTC/tasks/direct/crazyflie_ftc/models/meshes/Part_2_01_Part_2.obj" scale="1. 1. 1."/>
      </geometry>
    </collision>
    <collision>
      <origin xyz="0.0463155 0.0463155 -0.1499999" rpy="1.5707963 0.0000001 -2.3561945"/>
      <geometry>
        <mesh filename="file:///home/yubinkim/workspace/mtrl_am/file:/home/yubinkim/workspace/crazyflie_FTC/source/crazyflie_FTC/crazyflie_FTC/tasks/direct/crazyflie_ftc/models/meshes/Leg_02_Leg.obj" scale="1. 1. 1."/>
      </geometry>
    </collision>
    <collision>
      <origin xyz="-0.024 -0.03 -0.0129999" rpy="2.0532982 -1.5707963 -2.0532982"/>
      <geometry>
        <mesh filename="file:///home/yubinkim/workspace/mtrl_am/file:/home/yubinkim/workspace/crazyflie_FTC/source/crazyflie_FTC/crazyflie_FTC/tasks/direct/crazyflie_ftc/models/meshes/Base_Rail_Support_Grommet_Rail_Support_Grommet.obj" scale="1. 1. 1."/>
      </geometry>
    </collision>
    <collision>
      <origin xyz="-0.0420728 -0.0420729 0.0200001" rpy="1.5707964 -0.0000001 0.7853982"/>
      <geometry>
        <mesh filename="file:///home/yubinkim/workspace/mtrl_am/file:/home/yubinkim/workspace/crazyflie_FTC/source/crazyflie_FTC/crazyflie_FTC/tasks/direct/crazyflie_ftc/models/meshes/Base_Arm_White_Arm_White.obj" scale="1. 1. 1."/>
      </geometry>
    </collision>
    <collision>
      <origin xyz="0.024 -0.03 -0.0129999" rpy="1.0882958 1.5707963 1.0882958"/>
      <geometry>
        <mesh filename="file:///home/yubinkim/workspace/mtrl_am/file:/home/yubinkim/workspace/crazyflie_FTC/source/crazyflie_FTC/crazyflie_FTC/tasks/direct/crazyflie_ftc/models/meshes/Rail_Support_Grommet_01_Rail_Support_Grommet.obj" scale="1. 1. 1."/>
      </geometry>
    </collision>
    <collision>
      <origin xyz="-0.024 -0.03 -0.0129999" rpy="-1.5707964 -0.0000001 1.5707964"/>
      <geometry>
        <mesh filename="file:///home/yubinkim/workspace/mtrl_am/file:/home/yubinkim/workspace/crazyflie_FTC/source/crazyflie_FTC/crazyflie_FTC/tasks/direct/crazyflie_ftc/models/meshes/Rail_Support_01_Rail_Support.obj" scale="1. 1. 1."/>
      </geometry>
    </collision>
    <collision>
      <origin xyz="0.0565686 0.0353553 0.0200001" rpy="0. -0.0000001 0.7853982"/>
      <geometry>
        <mesh filename="file:///home/yubinkim/workspace/mtrl_am/file:/home/yubinkim/workspace/crazyflie_FTC/source/crazyflie_FTC/crazyflie_FTC/tasks/direct/crazyflie_ftc/models/meshes/Part_1_04_Part_1.obj" scale="1. 1. 1."/>
      </geometry>
    </collision>
    <collision>
      <origin xyz="-0.024 0.03 -0.0129999" rpy="1.0882958 1.5707963 1.0882958"/>
      <geometry>
        <mesh filename="file:///home/yubinkim/workspace/mtrl_am/file:/home/yubinkim/workspace/crazyflie_FTC/source/crazyflie_FTC/crazyflie_FTC/tasks/direct/crazyflie_ftc/models/meshes/Rail_Support_Grommet_02_Rail_Support_Grommet.obj" scale="1. 1. 1."/>
      </geometry>
    </collision>
    <collision>
      <origin xyz="-0.0339411 -0.0551543 0.0200001" rpy="0. -0.0000001 0.7853982"/>
      <geometry>
        <mesh filename="file:///home/yubinkim/workspace/mtrl_am/file:/home/yubinkim/workspace/crazyflie_FTC/source/crazyflie_FTC/crazyflie_FTC/tasks/direct/crazyflie_ftc/models/meshes/Part_1_05_Part_1.obj" scale="1. 1. 1."/>
      </geometry>
    </collision>
    <collision>
      <origin xyz="0.0353553 0.0565685 0.0200001" rpy="0.0000001 -0.0000001 0. "/>
      <geometry>
        <mesh filename="file:///home/yubinkim/workspace/mtrl_am/file:/home/yubinkim/workspace/crazyflie_FTC/source/crazyflie_FTC/crazyflie_FTC/tasks/direct/crazyflie_ftc/models/meshes/Part_1_06_Part_1.obj" scale="1. 1. 1."/>
      </geometry>
    </collision>
    <collision>
      <origin xyz="0.0565686 -0.0339411 0.0200001" rpy="0.0000001 0. -0.7853981"/>
      <geometry>
        <mesh filename="file:///home/yubinkim/workspace/mtrl_am/file:/home/yubinkim/workspace/crazyflie_FTC/source/crazyflie_FTC/crazyflie_FTC/tasks/direct/crazyflie_ftc/models/meshes/Part_1_07_Part_1.obj" scale="1. 1. 1."/>
      </geometry>
    </collision>
    <collision>
      <origin xyz="-0.1649006 -0.1649006 0.0511473" rpy="-0.041916 0.095993 0.372916"/>
      <geometry>
        <mesh filename="file:///home/yubinkim/workspace/mtrl_am/file:/home/yubinkim/workspace/crazyflie_FTC/source/crazyflie_FTC/crazyflie_FTC/tasks/direct/crazyflie_ftc/models/meshes/Part_2_02_Part_2.obj" scale="1. 1. 1."/>
      </geometry>
    </collision>
    <collision>
      <origin xyz="0.0091702 0. -0.0445247" rpy="1.5707963 -0.0000001 1.5707964"/>
      <geometry>
        <mesh filename="file:///home/yubinkim/workspace/mtrl_am/file:/home/yubinkim/workspace/crazyflie_FTC/source/crazyflie_FTC/crazyflie_FTC/tasks/direct/crazyflie_ftc/models/meshes/Battery_Plate_Support_01_Battery_Plate_Support.obj" scale="1. 1. 1."/>
      </geometry>
    </collision>
    <collision>
      <origin xyz="0. 0.03 -0.0129999" rpy="1.570811 -1.5671672 -1.570811 "/>
      <geometry>
        <mesh filename="file:///home/yubinkim/workspace/mtrl_am/file:/home/yubinkim/workspace/crazyflie_FTC/source/crazyflie_FTC/crazyflie_FTC/tasks/direct/crazyflie_ftc/models/meshes/Base_Rail_Rail.obj" scale="1. 1. 1."/>
      </geometry>
    </collision>
    <collision>
      <origin xyz="-0.0551543 0.0353553 0.0200001" rpy="0.0000001 -0.0000001 0. "/>
      <geometry>
        <mesh filename="file:///home/yubinkim/workspace/mtrl_am/file:/home/yubinkim/workspace/crazyflie_FTC/source/crazyflie_FTC/crazyflie_FTC/tasks/direct/crazyflie_ftc/models/meshes/Part_1_08_Part_1.obj" scale="1. 1. 1."/>
      </geometry>
    </collision>
    <collision>
      <origin xyz="-0.1649006 0.1649006 0.0511473" rpy="0.0133503 0.1038684 -0.6573337"/>
      <geometry>
        <mesh filename="file:///home/yubinkim/workspace/mtrl_am/file:/home/yubinkim/workspace/crazyflie_FTC/source/crazyflie_FTC/crazyflie_FTC/tasks/direct/crazyflie_ftc/models/meshes/Part_2_03_Part_2.obj" scale="1. 1. 1."/>
      </geometry>
    </collision>
    <collision>
      <origin xyz="-0.0339411 0.0565685 0.0200001" rpy="0. -0.0000001 0.7853982"/>
      <geometry>
        <mesh filename="file:///home/yubinkim/workspace/mtrl_am/file:/home/yubinkim/workspace/crazyflie_FTC/source/crazyflie_FTC/crazyflie_FTC/tasks/direct/crazyflie_ftc/models/meshes/Part_1_09_Part_1.obj" scale="1. 1. 1."/>
      </geometry>
    </collision>
    <collision>
      <origin xyz="-0.024 0.03 -0.0129999" rpy="-1.5707963 0.0000001 -1.5707964"/>
      <geometry>
        <mesh filename="file:///home/yubinkim/workspace/mtrl_am/file:/home/yubinkim/workspace/crazyflie_FTC/source/crazyflie_FTC/crazyflie_FTC/tasks/direct/crazyflie_ftc/models/meshes/Rail_Support_02_Rail_Support.obj" scale="1. 1. 1."/>
      </geometry>
    </collision>
    <collision>
      <origin xyz="0.0420729 0.0420729 0.0200001" rpy="1.5707963 0.0000001 -2.3561945"/>
      <geometry>
        <mesh filename="file:///home/yubinkim/workspace/mtrl_am/file:/home/yubinkim/workspace/crazyflie_FTC/source/crazyflie_FTC/crazyflie_FTC/tasks/direct/crazyflie_ftc/models/meshes/Arm_Blue_01_Arm_Blue.obj" scale="1. 1. 1."/>
      </geometry>
    </collision>
    <collision>
      <origin xyz="-0.1648932 0.1648932 0.0512468" rpy="-0.0741836 -0.0739802 -3.1388462"/>
      <geometry>
        <mesh filename="file:///home/yubinkim/workspace/mtrl_am/file:/home/yubinkim/workspace/crazyflie_FTC/source/crazyflie_FTC/crazyflie_FTC/tasks/direct/crazyflie_ftc/models/meshes/Part_1_10_Part_1.obj" scale="1. 1. 1."/>
      </geometry>
    </collision>
    <collision>
      <origin xyz="-0.0551543 -0.0339411 0.0200001" rpy="0.0000001 -0.0000001 0. "/>
      <geometry>
        <mesh filename="file:///home/yubinkim/workspace/mtrl_am/file:/home/yubinkim/workspace/crazyflie_FTC/source/crazyflie_FTC/crazyflie_FTC/tasks/direct/crazyflie_ftc/models/meshes/Part_1_11_Part_1.obj" scale="1. 1. 1."/>
      </geometry>
    </collision>
    <collision>
      <origin xyz="-0.0463155 0.0463155 -0.1499999" rpy="1.5707965 0. -0.7853981"/>
      <geometry>
        <mesh filename="file:///home/yubinkim/workspace/mtrl_am/file:/home/yubinkim/workspace/crazyflie_FTC/source/crazyflie_FTC/crazyflie_FTC/tasks/direct/crazyflie_ftc/models/meshes/Leg_03_Leg.obj" scale="1. 1. 1."/>
      </geometry>
    </collision>
    <collision>
      <origin xyz="0.024 0.03 -0.0129999" rpy="-1.5707964 -0.0000001 1.5707964"/>
      <geometry>
        <mesh filename="file:///home/yubinkim/workspace/mtrl_am/file:/home/yubinkim/workspace/crazyflie_FTC/source/crazyflie_FTC/crazyflie_FTC/tasks/direct/crazyflie_ftc/models/meshes/Rail_Support_03_Rail_Support.obj" scale="1. 1. 1."/>
      </geometry>
    </collision>
    <collision>
      <origin xyz="0. 0. 0.0000001" rpy="1.5707964 -0.0000001 0. "/>
      <geometry>
        <mesh filename="file:///home/yubinkim/workspace/mtrl_am/file:/home/yubinkim/workspace/crazyflie_FTC/source/crazyflie_FTC/crazyflie_FTC/tasks/direct/crazyflie_ftc/models/meshes/Base_Bottom_Plate_Bottom_Plate.obj" scale="1. 1. 1."/>
      </geometry>
    </collision>
    <collision>
      <origin xyz="0.024 0.03 -0.0129999" rpy="2.0532982 -1.5707963 -2.0532982"/>
      <geometry>
        <mesh filename="file:///home/yubinkim/workspace/mtrl_am/file:/home/yubinkim/workspace/crazyflie_FTC/source/crazyflie_FTC/crazyflie_FTC/tasks/direct/crazyflie_ftc/models/meshes/Rail_Support_Grommet_03_Rail_Support_Grommet.obj" scale="1. 1. 1."/>
      </geometry>
    </collision>
    <collision>
      <origin xyz="-0.0420728 0.0420729 0.0200001" rpy="1.5707965 0. -0.7853981"/>
      <geometry>
        <mesh filename="file:///home/yubinkim/workspace/mtrl_am/file:/home/yubinkim/workspace/crazyflie_FTC/source/crazyflie_FTC/crazyflie_FTC/tasks/direct/crazyflie_ftc/models/meshes/Arm_White_01_Arm_White.obj" scale="1. 1. 1."/>
      </geometry>
    </collision>
    <collision>
      <origin xyz="0.0353553 -0.0551543 0.0200001" rpy="0. -0.0000001 0.7853982"/>
      <geometry>
        <mesh filename="file:///home/yubinkim/workspace/mtrl_am/file:/home/yubinkim/workspace/crazyflie_FTC/source/crazyflie_FTC/crazyflie_FTC/tasks/direct/crazyflie_ftc/models/meshes/Part_1_12_Part_1.obj" scale="1. 1. 1."/>
      </geometry>
    </collision>
    <collision>
      <origin xyz="0. -0.03 -0.0129999" rpy="1.0882958 1.5707963 1.0882958"/>
      <geometry>
        <mesh filename="file:///home/yubinkim/workspace/mtrl_am/file:/home/yubinkim/workspace/crazyflie_FTC/source/crazyflie_FTC/crazyflie_FTC/tasks/direct/crazyflie_ftc/models/meshes/Rail_01_Rail.obj" scale="1. 1. 1."/>
      </geometry>
    </collision>
  </link>
</robot>
